Workbook

Sheet Dashboard
B2: Superstore Sales Performance Dashboard
B3: =IF(LEFT(Data!$B$2,5)="DEMO-","SAMPLE DEMO DATA (synthetic) - paste the Kaggle Superstore data into the Data sheet, see README tab.","Data loaded: "&TEXT(COUNTA(Data!$B$2:$B$12000),"#,##0")&" line items. Use the yellow dropdowns to filter everything.") -> SAMPLE DEMO DATA (synthetic) - paste the Kaggle Superstore data into the Data sheet, see README tab.
B5: Year: | C5: All | E5: Region: | F5: All | H5: Category: | I5: All | L5: Segment: | M5: All | P5: Pick 'All' to clear a filter
B7: TOTAL SALES | E7: TOTAL PROFIT | H7: PROFIT MARGIN | K7: ORDERS | N7: UNITS SOLD | Q7: AVG DISCOUNT
B8: =SUMIFS(Data!$R$2:$R$12000,Data!$V$2:$V$12000,Calc!$B$3,Data!$M$2:$M$12000,Calc!$B$4,Data!$O$2:$O$12000,Calc!$B$5,Data!$H$2:$H$12000,Calc!$B$6) -> 834817.62 | E8: =SUMIFS(Data!$U$2:$U$12000,Data!$V$2:$V$12000,Calc!$B$3,Data!$M$2:$M$12000,Calc!$B$4,Data!$O$2:$O$12000,Calc!$B$5,Data!$H$2:$H$12000,Calc!$B$6) -> 57210.94 | H8: =IFERROR(E8/B8,0) -> 0.068531064 | K8: =SUMIFS(Data!$Z$2:$Z$12000,Data!$V$2:$V$12000,Calc!$B$3,Data!$M$2:$M$12000,Calc!$B$4,Data!$O$2:$O$12000,Calc!$B$5,Data!$H$2:$H$12000,Calc!$B$6) -> 428 | N8: =SUMIFS(Data!$S$2:$S$12000,Data!$V$2:$V$12000,Calc!$B$3,Data!$M$2:$M$12000,Calc!$B$4,Data!$O$2:$O$12000,Calc!$B$5,Data!$H$2:$H$12000,Calc!$B$6) -> 3666 | Q8: =IFERROR(AVERAGEIFS(Data!$T$2:$T$12000,Data!$V$2:$V$12000,Calc!$B$3,Data!$M$2:$M$12000,Calc!$B$4,Data!$O$2:$O$12000,Calc!$B$5,Data!$H$2:$H$12000,Calc!$B$6),0) -> 0.201125
B79: Key insights (update automatically with the filters)
B80: =IFERROR(IF(SUM(Calc!$B$33:$B$36)=0,"No data for the current filters.","Top region: "&INDEX(Calc!$A$33:$A$36,MATCH(MAX(Calc!$B$33:$B$36),Calc!$B$33:$B$36,0))&" with "&TEXT(MAX(Calc!$B$33:$B$36),"$#,##0")&" in sales ("&TEXT(MAX(Calc!$B$33:$B$36)/SUM(Calc!$B$33:$B$36),"0%")&" of the total across regions)."),"") -> Top region: Central with $238,442 in sales (29% of the total across regions).
B81: =IFERROR(IF(SUM(Calc!$B$11:$B$22)=0,"","Peak month: "&INDEX(Calc!$A$11:$A$22,MATCH(MAX(Calc!$B$11:$B$22),Calc!$B$11:$B$22,0))&" with "&TEXT(MAX(Calc!$B$11:$B$22),"$#,##0")&" in sales."),"") -> Peak month: Nov with $112,564 in sales.
B82: =IFERROR(IF(Calc!$H$79=0,"","Top state: "&Calc!$G$79&" with "&TEXT(Calc!$H$79,"$#,##0")&" in sales."),"") -> Top state: Louisiana with $53,392 in sales.
B83: =IFERROR("Lowest-profit sub-category: "&INDEX(Calc!$A$52:$A$68,MATCH(MIN(Calc!$C$52:$C$68),Calc!$C$52:$C$68,0))&" ("&TEXT(MIN(Calc!$C$52:$C$68),"$#,##0;-$#,##0")&" profit).","") -> Lowest-profit sub-category: Tables (-$17,788 profit).
B84: =IFERROR("Lowest profit margin: "&INDEX(Calc!$A$52:$A$68,MATCH(MIN(Calc!$D$52:$D$68),Calc!$D$52:$D$68,0))&" at "&TEXT(MIN(Calc!$D$52:$D$68),"0.0%")&".","") -> Lowest profit margin: Tables at -17.2%.
B85: =IFERROR(IF(OR(Calc!$D$72="",Calc!$D$75=""),"","Profit margin is "&TEXT(Calc!$D$72,"0.0%")&" on undiscounted line items versus "&TEXT(Calc!$D$75,"0.0%")&" on items discounted over 40%."),"") -> Profit margin is 14.6% on undiscounted line items versus -25.8% on items discounted over 40%.
B87: ="Data check: "&COUNTA(Data!$B$2:$B$12000)&" line items loaded; "&(COUNTA(Data!$C$2:$C$12000)-COUNT(Data!$C$2:$C$12000))&" rows have an Order Date Excel cannot read as a date (they are excluded from every figure above)." -> Data check: 800 line items loaded; 0 rows have an Order Date Excel cannot read as a date (they are excluded from every figure above).

Sheet README
A1: Superstore Sales Dashboard - how to use
A3: This workbook currently holds about 800 rows of SYNTHETIC demo data (Order IDs start with DEMO-) so you can see the dashboard working. Replace it with the real Kaggle data:
A5: 1. Download the dataset: https://www.kaggle.com/datasets/vivek468/superstore-dataset-final (free Kaggle login needed). Unzip to get Sample - Superstore.csv.
A6: 2. In a NEW Excel workbook use Data > From Text/CSV. Set File Origin to 1252: Western European (Windows) (or 65001: UTF-8), then Load.
A7: 3. Indian regional settings: the dates in the file are month/day/year (US style). If dates load as text or look wrong, use Transform Data and, for Order Date and Ship Date, Change Type > Using Locale > Date > English (United States).
A8: 4. On the Data sheet of this workbook, select A2:U1000 (the demo rows) and press Delete. Do NOT delete the header row or columns V:Z (they are formulas, pre-filled to row 12,000).
A9: 5. Copy the 21 columns of the real data (same column order as the headers in row 1) and paste them at Data!A2. Press F9 if the numbers do not refresh.
A10: 6. Go to the Dashboard. The amber banner disappears and every figure updates. Use the yellow dropdowns (Year, Region, Category, Segment) to filter.
A12: Notes and limits
A13: - Formulas read Data rows 2 to 12,000. The Kaggle file has 9,994 rows, so it fits. Larger files need the ranges extended.
A14: - The Year dropdown lists 2014-2017 (the years in this dataset). Edit the list via Data > Data Validation if your data differs.
A15: - The Top 10 states list uses the 49 states that appear in the Kaggle file (Calc sheet, column A).
... A21: Sheets: Dashboard (what you present) | README | Data (paste the CSV here) | Calc (summary tables feeding the charts)

Sheet Data
A1: Row ID | B1: Order ID | C1: Order Date | D1: Ship Date | E1: Ship Mode | F1: Customer ID | G1: Customer Name | H1: Segment | I1: Country | J1: City | K1: State | L1: Postal Code | M1: Region | N1: Product ID | O1: Category | P1: Sub-Category | Q1: Product Name | R1: Sales | S1: Quantity | T1: Discount | U1: Profit | V1: Year | W1: Month | X1: Discount Band | Y1: Shipping Days | Z1: Order Flag
A2: 1 | B2: DEMO-0001 | C2: 41641 | D2: 41646 | E2: Second Class | F2: DC-1025 | G2: Demo Customer 25 | H2: Consumer | I2: United States | J2: Demo City | K2: South Carolina | L2: 92168 | M2: South | N2: DEMO-COP-1254 | O2: Technology | P2: Copiers | Q2: Demo Copiers item 55 | R2: 11980.88 | S2: 8 | T2: 0.2 | U2: 2743.92 | V2: =IF(ISNUMBER(C2),YEAR(C2),"") -> 2014 | W2: =IF(ISNUMBER(C2),MONTH(C2),"") -> 1 | X2: =IF(T2="","",IF(T2=0,"No discount",IF(T2<=0.2,"Low (1-20%)",IF(T2<=0.4,"Medium (21-40%)","High (>40%)")))) -> Low (1-20%) | Y2: =IF(AND(ISNUMBER(C2),ISNUMBER(D2)),D2-C2,"") -> 5 | Z2: =IF(B2="","",IF(MATCH(B2,$B$2:$B$12000,0)=ROW()-1,1,0)) -> 1
A3: 2 | B3: DEMO-0002 | C3: 41649 | D3: 41655 | E3: Standard Class | F3: DC-1001 | G3: Demo Customer 01 | H3: Consumer | I3: United States | J3: Demo City | K3: Alabama | L3: 46103 | M3: South | N3: DEMO-ART-4969 | O3: Office Supplies | P3: Art | Q3: Demo Art item 58 | R3: 48.37 | S3: 4 | T3: 0 | U3: 13.45 | V3: =IF(ISNUMBER(C3),YEAR(C3),"") -> 2014 | W3: =IF(ISNUMBER(C3),MONTH(C3),"") -> 1 | X3: =IF(T3="","",IF(T3=0,"No discount",IF(T3<=0.2,"Low (1-20%)",IF(T3<=0.4,"Medium (21-40%)","High (>40%)")))) -> No discount | Y3: =IF(AND(ISNUMBER(C3),ISNUMBER(D3)),D3-C3,"") -> 6 | Z3: =IF(B3="","",IF(MATCH(B3,$B$2:$B$12000,0)=ROW()-1,1,0)) -> 1
A4: 3 | B4: DEMO-0002 | C4: 41649 | D4: 41655 | E4: Standard Class | F4: DC-1001 | G4: Demo Customer 01 | H4: Consumer | I4: United States | J4: Demo City | K4: Alabama | L4: 48422 | M4: South | N4: DEMO-BIN-9160 | O4: Office Supplies | P4: Binders | Q4: Demo Binders item 59 | R4: 62.83 | S4: 1 | T4: 0.2 | U4: 9.91 | V4: =IF(ISNUMBER(C4),YEAR(C4),"") -> 2014 | W4: =IF(ISNUMBER(C4),MONTH(C4),"") -> 1 | X4: =IF(T4="","",IF(T4=0,"No discount",IF(T4<=0.2,"Low (1-20%)",IF(T4<=0.4,"Medium (21-40%)","High (>40%)")))) -> Low (1-20%) | Y4: =IF(AND(ISNUMBER(C4),ISNUMBER(D4)),D4-C4,"") -> 6 | Z4: =IF(B4="","",IF(MATCH(B4,$B$2:$B$12000,0)=ROW()-1,1,0)) -> 0
A5: 4 | B5: DEMO-0003 | C5: 41656 | D5: 41657 | E5: Standard Class | F5: DC-1043 | G5: Demo Customer 43 | H5: Corporate | I5: United States | J5: Demo City | K5: Louisiana | L5: 60980 | M5: South | N5: DEMO-APP-6096 | O5: Office Supplies | P5: Appliances | Q5: Demo Appliances item 40 | R5: 445.17 | S5: 1 | T5: 0 | U5: 24.14 | V5: =IF(ISNUMBER(C5),YEAR(C5),"") -> 2014 | W5: =IF(ISNUMBER(C5),MONTH(C5),"") -> 1 | X5: =IF(T5="","",IF(T5=0,"No discount",IF(T5<=0.2,"Low (1-20%)",IF(T5<=0.4,"Medium (21-40%)","High (>40%)")))) -> No discount | Y5: =IF(AND(ISNUMBER(C5),ISNUMBER(D5)),D5-C5,"") -> 1 | Z5: =IF(B5="","",IF(MATCH(B5,$B$2:$B$12000,0)=ROW()-1,1,0)) -> 1
A6: 5 | B6: DEMO-0003 | C6: 41656 | D6: 41657 | E6: Same Day | F6: DC-1043 | G6: Demo Customer 43 | H6: Corporate | I6: United States | J6: Demo City | K6: Louisiana | L6: 71577 | M6: South | N6: DEMO-BIN-3727 | O6: Office Supplies | P6: Binders | Q6: Demo Binders item 19 | R6: 42.72 | S6: 8 | T6: 0.5 | U6: -1.88 | V6: =IF(ISNUMBER(C6),YEAR(C6),"") -> 2014 | W6: =IF(ISNUMBER(C6),MONTH(C6),"") -> 1 | X6: =IF(T6="","",IF(T6=0,"No discount",IF(T6<=0.2,"Low (1-20%)",IF(T6<=0.4,"Medium (21-40%)","High (>40%)")))) -> High (>40%) | Y6: =IF(AND(ISNUMBER(C6),ISNUMBER(D6)),D6-C6,"") -> 1 | Z6: =IF(B6="","",IF(MATCH(B6,$B$2:$B$12000,0)=ROW()-1,1,0)) -> 0
A7: 6 | B7: DEMO-0004 | C7: 41657 | D7: 41660 | E7: Same Day | F7: DC-1052 | G7: Demo Customer 52 | H7: Consumer | I7: United States | J7: Demo City | K7: District of Columbia | L7: 45649 | M7: East | N7: DEMO-COP-6470 | O7: Technology | P7: Copiers | Q7: Demo Copiers item 38 | R7: 7175.28 | S7: 7 | T7: 0.3 | U7: 1208.02 | V7: =IF(ISNUMBER(C7),YEAR(C7),"") -> 2014 | W7: =IF(ISNUMBER(C7),MONTH(C7),"") -> 1 | X7: =IF(T7="","",IF(T7=0,"No discount",IF(T7<=0.2,"Low (1-20%)",IF(T7<=0.4,"Medium (21-40%)","High (>40%)")))) -> Medium (21-40%) | Y7: =IF(AND(ISNUMBER(C7),ISNUMBER(D7)),D7-C7,"") -> 3 | Z7: =IF(B7="","",IF(MATCH(B7,$B$2:$B$12000,0)=ROW()-1,1,0)) -> 1
A8: 7 | B8: DEMO-0004 | C8: 41657 | D8: 41660 | E8: Second Class | F8: DC-1052 | G8: Demo Customer 52 | H8: Consumer | I8: United States | J8: Demo City | K8: District of Columbia | L8: 59371 | M8: East | N8: DEMO-LAB-7346 | O8: Office Supplies | P8: Labels | Q8: Demo Labels item 88 | R8: 25.64 | S8: 1 | T8: 0 | U8: 9.77 | V8: =IF(ISNUMBER(C8),YEAR(C8),"") -> 2014 | W8: =IF(ISNUMBER(C8),MONTH(C8),"") -> 1 | X8: =IF(T8="","",IF(T8=0,"No discount",IF(T8<=0.2,"Low (1-20%)",IF(T8<=0.4,"Medium (21-40%)","High (>40%)")))) -> No discount | Y8: =IF(AND(ISNUMBER(C8),ISNUMBER(D8)),D8-C8,"") -> 3 | Z8: =IF(B8="","",IF(MATCH(B8,$B$2:$B$12000,0)=ROW()-1,1,0)) -> 0
A9: 8 | B9: DEMO-0005 | C9: 41660 | D9: 41667 | E9: First Class | F9: DC-1025 | G9: Demo Customer 25 | H9: Consumer | I9: United States | J9: Demo City | K9: South Carolina | L9: 65377 | M9: South | N9: DEMO-PHO-3576 | O9: Technology | P9: Phones | Q9: Demo Phones item 76 | R9: 1718.26 | S9: 5 | T9: 0 | U9: 342.54 | V9: =IF(ISNUMBER(C9),YEAR(C9),"") -> 2014 | W9: =IF(ISNUMBER(C9),MONTH(C9),"") -> 1 | X9: =IF(T9="","",IF(T9=0,"No discount",IF(T9<=0.2,"Low (1-20%)",IF(T9<=0.4,"Medium (21-40%)","High (>40%)")))) -> No discount | Y9: =IF(AND(ISNUMBER(C9),ISNUMBER(D9)),D9-C9,"") -> 7 | Z9: =IF(B9="","",IF(MATCH(B9,$B$2:$B$12000,0)=ROW()-1,1,0)) -> 1
A10: 9 | B10: DEMO-0006 | C10: 41666 | D10: 41673 | E10: Same Day | F10: DC-1059 | G10: Demo Customer 59 | H10: Corporate | I10: United States | J10: Demo City | K10: Wyoming | L10: 55462 | M10: West | N10: DEMO-CHA-9758 | O10: Furniture | P10: Chairs | Q10: Demo Chairs item 11 | R10: 1850.1 | S10: 3 | T10: 0.1 | U10: 108.11 | V10: =IF(ISNUMBER(C10),YEAR(C10),"") -> 2014 | W10: =IF(ISNUMBER(C10),MONTH(C10),"") -> 1 | X10: =IF(T10="","",IF(T10=0,"No discount",IF(T10<=0.2,"Low (1-20%)",IF(T10<=0.4,"Medium (21-40%)","High (>40%)")))) -> Low (1-20%) | Y10: =IF(AND(ISNUMBER(C10),ISNUMBER(D10)),D10-C10,"") -> 7 | Z10: =IF(B10="","",IF(MATCH(B10,$B$2:$B$12000,0)=ROW()-1,1,0)) -> 1
A11: 10 | B11: DEMO-0007 | C11: 41671 | D11: 41675 | E11: Same Day | F11: DC-1035 | G11: Demo Customer 35 | H11: Consumer | I11: United States | J11: Demo City | K11: Oregon | L11: 70990 | M11: West | N11: DEMO-ENV-4384 | O11: Office Supplies | P11: Envelopes | Q11: Demo Envelopes item 33 | R11: 138.17 | S11: 4 | T11: 0.1 | U11: 31.75 | V11: =IF(ISNUMBER(C11),YEAR(C11),"") -> 2014 | W11: =IF(ISNUMBER(C11),MONTH(C11),"") -> 2 | X11: =IF(T11="","",IF(T11=0,"No discount",IF(T11<=0.2,"Low (1-20%)",IF(T11<=0.4,"Medium (21-40%)","High (>40%)")))) -> Low (1-20%) | Y11: =IF(AND(ISNUMBER(C11),ISNUMBER(D11)),D11-C11,"") -> 4 | Z11: =IF(B11="","",IF(MATCH(B11,$B$2:$B$12000,0)=ROW()-1,1,0)) -> 1
A12: 11 | B12: DEMO-0008 | C12: 41672 | D12: 41673 | E12: First Class | F12: DC-1038 | G12: Demo Customer 38 | H12: Consumer | I12: United States | J12: Demo City | K12: Wyoming | L12: 78401 | M12: West | N12: DEMO-STO-6259 | O12: Office Supplies | P12: Storage | Q12: Demo Storage item 62 | R12: 293.85 | S12: 2 | T12: 0.4 | U12: -39.65 | V12: =IF(ISNUMBER(C12),YEAR(C12),"") -> 2014 | W12: =IF(ISNUMBER(C12),MONTH(C12),"") -> 2 | X12: =IF(T12="","",IF(T12=0,"No discount",IF(T12<=0.2,"Low (1-20%)",IF(T12<=0.4,"Medium (21-40%)","High (>40%)")))) -> Medium (21-40%) | Y12: =IF(AND(ISNUMBER(C12),ISNUMBER(D12)),D12-C12,"") -> 1 | Z12: =IF(B12="","",IF(MATCH(B12,$B$2:$B$12000,0)=ROW()-1,1,0)) -> 1
A13: 12 | B13: DEMO-0009 | C13: 41679 | D13: 41681 | E13: First Class | F13: DC-1033 | G13: Demo Customer 33 | H13: Corporate | I13: United States | J13: Demo City | K13: Rhode Island | L13: 57556 | M13: East | N13: DEMO-CHA-6880 | O13: Furniture | P13: Chairs | Q13: Demo Chairs item 52 | R13: 1167.04 | S13: 2 | T13: 0 | U13: 74.63 | V13: =IF(ISNUMBER(C13),YEAR(C13),"") -> 2014 | W13: =IF(ISNUMBER(C13),MONTH(C13),"") -> 2 | X13: =IF(T13="","",IF(T13=0,"No discount",IF(T13<=0.2,"Low (1-20%)",IF(T13<=0.4,"Medium (21-40%)","High (>40%)")))) -> No discount | Y13: =IF(AND(ISNUMBER(C13),ISNUMBER(D13)),D13-C13,"") -> 2 | Z13: =IF(B13="","",IF(MATCH(B13,$B$2:$B$12000,0)=ROW()-1,1,0)) -> 1
... A801: 800 | B801: DEMO-0428 | C801: 43097 | D801: 43098 | E801: Standard Class | F801: DC-1040 | G801: Demo Customer 40 | H801: Corporate | I801: United States | J801: Demo City | K801: Washington | L801: 88414 | M801: West | N801: DEMO-STO-7980 | O801: Office Supplies | P801: Storage | Q801: Demo Storage item 41 | R801: 333.09 | S801: 2 | T801: 0.4 | U801: -29.83 | V801: =IF(ISNUMBER(C801),YEAR(C801),"") -> 2017 | W801: =IF(ISNUMBER(C801),MONTH(C801),"") -> 12 | X801: =IF(T801="","",IF(T801=0,"No discount",IF(T801<=0.2,"Low (1-20%)",IF(T801<=0.4,"Medium (21-40%)","High (>40%)")))) -> Medium (21-40%) | Y801: =IF(AND(ISNUMBER(C801),ISNUMBER(D801)),D801-C801,"") -> 1 | Z801: =IF(B801="","",IF(MATCH(B801,$B$2:$B$12000,0)=ROW()-1,1,0)) -> 1
V802: =IF(ISNUMBER(C802),YEAR(C802),"") | W802: =IF(ISNUMBER(C802),MONTH(C802),"") | X802: =IF(T802="","",IF(T802=0,"No discount",IF(T802<=0.2,"Low (1-20%)",IF(T802<=0.4,"Medium (21-40%)","High (>40%)")))) | Y802: =IF(AND(ISNUMBER(C802),ISNUMBER(D802)),D802-C802,"") | Z802: =IF(B802="","",IF(MATCH(B802,$B$2:$B$12000,0)=ROW()-1,1,0))
V803: =IF(ISNUMBER(C803),YEAR(C803),"") | W803: =IF(ISNUMBER(C803),MONTH(C803),"") | X803: =IF(T803="","",IF(T803=0,"No discount",IF(T803<=0.2,"Low (1-20%)",IF(T803<=0.4,"Medium (21-40%)","High (>40%)")))) | Y803: =IF(AND(ISNUMBER(C803),ISNUMBER(D803)),D803-C803,"") | Z803: =IF(B803="","",IF(MATCH(B803,$B$2:$B$12000,0)=ROW()-1,1,0))
V804: =IF(ISNUMBER(C804),YEAR(C804),"") | W804: =IF(ISNUMBER(C804),MONTH(C804),"") | X804: =IF(T804="","",IF(T804=0,"No discount",IF(T804<=0.2,"Low (1-20%)",IF(T804<=0.4,"Medium (21-40%)","High (>40%)")))) | Y804: =IF(AND(ISNUMBER(C804),ISNUMBER(D804)),D804-C804,"") | Z804: =IF(B804="","",IF(MATCH(B804,$B$2:$B$12000,0)=ROW()-1,1,0))
V805: =IF(ISNUMBER(C805),YEAR(C805),"") | W805: =IF(ISNUMBER(C805),MONTH(C805),"") | X805: =IF(T805="","",IF(T805=0,"No discount",IF(T805<=0.2,"Low (1-20%)",IF(T805<=0.4,"Medium (21-40%)","High (>40%)")))) | Y805: =IF(AND(ISNUMBER(C805),ISNUMBER(D805)),D805-C805,"") | Z805: =IF(B805="","",IF(MATCH(B805,$B$2:$B$12000,0)=ROW()-1,1,0))
V806: =IF(ISNUMBER(C806),YEAR(C806),"") | W806: =IF(ISNUMBER(C806),MONTH(C806),"") | X806: =IF(T806="","",IF(T806=0,"No discount",IF(T806<=0.2,"Low (1-20%)",IF(T806<=0.4,"Medium (21-40%)","High (>40%)")))) | Y806: =IF(AND(ISNUMBER(C806),ISNUMBER(D806)),D806-C806,"") | Z806: =IF(B806="","",IF(MATCH(B806,$B$2:$B$12000,0)=ROW()-1,1,0))
V807: =IF(ISNUMBER(C807),YEAR(C807),"") | W807: =IF(ISNUMBER(C807),MONTH(C807),"") | X807: =IF(T807="","",IF(T807=0,"No discount",IF(T807<=0.2,"Low (1-20%)",IF(T807<=0.4,"Medium (21-40%)","High (>40%)")))) | Y807: =IF(AND(ISNUMBER(C807),ISNUMBER(D807)),D807-C807,"") | Z807: =IF(B807="","",IF(MATCH(B807,$B$2:$B$12000,0)=ROW()-1,1,0))
V808: =IF(ISNUMBER(C808),YEAR(C808),"") | W808: =IF(ISNUMBER(C808),MONTH(C808),"") | X808: =IF(T808="","",IF(T808=0,"No discount",IF(T808<=0.2,"Low (1-20%)",IF(T808<=0.4,"Medium (21-40%)","High (>40%)")))) | Y808: =IF(AND(ISNUMBER(C808),ISNUMBER(D808)),D808-C808,"") | Z808: =IF(B808="","",IF(MATCH(B808,$B$2:$B$12000,0)=ROW()-1,1,0))
V809: =IF(ISNUMBER(C809),YEAR(C809),"") | W809: =IF(ISNUMBER(C809),MONTH(C809),"") | X809: =IF(T809="","",IF(T809=0,"No discount",IF(T809<=0.2,"Low (1-20%)",IF(T809<=0.4,"Medium (21-40%)","High (>40%)")))) | Y809: =IF(AND(ISNUMBER(C809),ISNUMBER(D809)),D809-C809,"") | Z809: =IF(B809="","",IF(MATCH(B809,$B$2:$B$12000,0)=ROW()-1,1,0))
V810: =IF(ISNUMBER(C810),YEAR(C810),"") | W810: =IF(ISNUMBER(C810),MONTH(C810),"") | X810: =IF(T810="","",IF(T810=0,"No discount",IF(T810<=0.2,"Low (1-20%)",IF(T810<=0.4,"Medium (21-40%)","High (>40%)")))) | Y810: =IF(AND(ISNUMBER(C810),ISNUMBER(D810)),D810-C810,"") | Z810: =IF(B810="","",IF(MATCH(B810,$B$2:$B$12000,0)=ROW()-1,1,0))
V811: =IF(ISNUMBER(C811),YEAR(C811),"") | W811: =IF(ISNUMBER(C811),MONTH(C811),"") | X811: =IF(T811="","",IF(T811=0,"No discount",IF(T811<=0.2,"Low (1-20%)",IF(T811<=0.4,"Medium (21-40%)","High (>40%)")))) | Y811: =IF(AND(ISNUMBER(C811),ISNUMBER(D811)),D811-C811,"") | Z811: =IF(B811="","",IF(MATCH(B811,$B$2:$B$12000,0)=ROW()-1,1,0))
V812: =IF(ISNUMBER(C812),YEAR(C812),"") | W812: =IF(ISNUMBER(C812),MONTH(C812),"") | X812: =IF(T812="","",IF(T812=0,"No discount",IF(T812<=0.2,"Low (1-20%)",IF(T812<=0.4,"Medium (21-40%)","High (>40%)")))) | Y812: =IF(AND(ISNUMBER(C812),ISNUMBER(D812)),D812-C812,"") | Z812: =IF(B812="","",IF(MATCH(B812,$B$2:$B$12000,0)=ROW()-1,1,0))
V813: =IF(ISNUMBER(C813),YEAR(C813),"") | W813: =IF(ISNUMBER(C813),MONTH(C813),"") | X813: =IF(T813="","",IF(T813=0,"No discount",IF(T813<=0.2,"Low (1-20%)",IF(T813<=0.4,"Medium (21-40%)","High (>40%)")))) | Y813: =IF(AND(ISNUMBER(C813),ISNUMBER(D813)),D813-C813,"") | Z813: =IF(B813="","",IF(MATCH(B813,$B$2:$B$12000,0)=ROW()-1,1,0))
... V12000: =IF(ISNUMBER(C12000),YEAR(C12000),"") | W12000: =IF(ISNUMBER(C12000),MONTH(C12000),"") | X12000: =IF(T12000="","",IF(T12000=0,"No discount",IF(T12000<=0.2,"Low (1-20%)",IF(T12000<=0.4,"Medium (21-40%)","High (>40%)")))) | Y12000: =IF(AND(ISNUMBER(C12000),ISNUMBER(D12000)),D12000-C12000,"") | Z12000: =IF(B12000="","",IF(MATCH(B12000,$B$2:$B$12000,0)=ROW()-1,1,0))

Sheet Calc
A1: Calculation sheet - feeds the Dashboard (do not edit)
A3: Year criterion | B3: =IF(Dashboard!$C$5="All",">0",Dashboard!$C$5) -> >0
A4: Region criterion | B4: =IF(Dashboard!$F$5="All","*",Dashboard!$F$5) -> *
A5: Category criterion | B5: =IF(Dashboard!$I$5="All","*",Dashboard!$I$5) -> *
A6: Segment criterion | B6: =IF(Dashboard!$M$5="All","*",Dashboard!$M$5) -> *
A9: Monthly trend (follows all filters)
A10: Month | B10: Sales | C10: Profit | D10: Margin | E10: Month #
A11: Jan | B11: =SUMIFS(Data!$R$2:$R$12000,Data!$W$2:$W$12000,$E11,Data!$V$2:$V$12000,Calc!$B$3,Data!$M$2:$M$12000,Calc!$B$4,Data!$O$2:$O$12000,Calc!$B$5,Data!$H$2:$H$12000,Calc!$B$6) -> 61176.24 | C11: =SUMIFS(Data!$U$2:$U$12000,Data!$W$2:$W$12000,$E11,Data!$V$2:$V$12000,Calc!$B$3,Data!$M$2:$M$12000,Calc!$B$4,Data!$O$2:$O$12000,Calc!$B$5,Data!$H$2:$H$12000,Calc!$B$6) -> 9798.36 | D11: =IF(B11=0,"",C11/B11) -> 0.1601661 | E11: 1
A12: Feb | B12: =SUMIFS(Data!$R$2:$R$12000,Data!$W$2:$W$12000,$E12,Data!$V$2:$V$12000,Calc!$B$3,Data!$M$2:$M$12000,Calc!$B$4,Data!$O$2:$O$12000,Calc!$B$5,Data!$H$2:$H$12000,Calc!$B$6) -> 49436.07 | C12: =SUMIFS(Data!$U$2:$U$12000,Data!$W$2:$W$12000,$E12,Data!$V$2:$V$12000,Calc!$B$3,Data!$M$2:$M$12000,Calc!$B$4,Data!$O$2:$O$12000,Calc!$B$5,Data!$H$2:$H$12000,Calc!$B$6) -> 1779.54 | D12: =IF(B12=0,"",C12/B12) -> 0.035996793 | E12: 2
A13: Mar | B13: =SUMIFS(Data!$R$2:$R$12000,Data!$W$2:$W$12000,$E13,Data!$V$2:$V$12000,Calc!$B$3,Data!$M$2:$M$12000,Calc!$B$4,Data!$O$2:$O$12000,Calc!$B$5,Data!$H$2:$H$12000,Calc!$B$6) -> 43504.47 | C13: =SUMIFS(Data!$U$2:$U$12000,Data!$W$2:$W$12000,$E13,Data!$V$2:$V$12000,Calc!$B$3,Data!$M$2:$M$12000,Calc!$B$4,Data!$O$2:$O$12000,Calc!$B$5,Data!$H$2:$H$12000,Calc!$B$6) -> 1159.41 | D13: =IF(B13=0,"",C13/B13) -> 0.026650365 | E13: 3
A14: Apr | B14: =SUMIFS(Data!$R$2:$R$12000,Data!$W$2:$W$12000,$E14,Data!$V$2:$V$12000,Calc!$B$3,Data!$M$2:$M$12000,Calc!$B$4,Data!$O$2:$O$12000,Calc!$B$5,Data!$H$2:$H$12000,Calc!$B$6) -> 56716.21 | C14: =SUMIFS(Data!$U$2:$U$12000,Data!$W$2:$W$12000,$E14,Data!$V$2:$V$12000,Calc!$B$3,Data!$M$2:$M$12000,Calc!$B$4,Data!$O$2:$O$12000,Calc!$B$5,Data!$H$2:$H$12000,Calc!$B$6) -> 5908.59 | D14: =IF(B14=0,"",C14/B14) -> 0.10417815 | E14: 4
A15: May | B15: =SUMIFS(Data!$R$2:$R$12000,Data!$W$2:$W$12000,$E15,Data!$V$2:$V$12000,Calc!$B$3,Data!$M$2:$M$12000,Calc!$B$4,Data!$O$2:$O$12000,Calc!$B$5,Data!$H$2:$H$12000,Calc!$B$6) -> 84377.29 | C15: =SUMIFS(Data!$U$2:$U$12000,Data!$W$2:$W$12000,$E15,Data!$V$2:$V$12000,Calc!$B$3,Data!$M$2:$M$12000,Calc!$B$4,Data!$O$2:$O$12000,Calc!$B$5,Data!$H$2:$H$12000,Calc!$B$6) -> 2912.71 | D15: =IF(B15=0,"",C15/B15) -> 0.034520071 | E15: 5
A16: Jun | B16: =SUMIFS(Data!$R$2:$R$12000,Data!$W$2:$W$12000,$E16,Data!$V$2:$V$12000,Calc!$B$3,Data!$M$2:$M$12000,Calc!$B$4,Data!$O$2:$O$12000,Calc!$B$5,Data!$H$2:$H$12000,Calc!$B$6) -> 75099.47 | C16: =SUMIFS(Data!$U$2:$U$12000,Data!$W$2:$W$12000,$E16,Data!$V$2:$V$12000,Calc!$B$3,Data!$M$2:$M$12000,Calc!$B$4,Data!$O$2:$O$12000,Calc!$B$5,Data!$H$2:$H$12000,Calc!$B$6) -> 5246.94 | D16: =IF(B16=0,"",C16/B16) -> 0.069866538 | E16: 6
A17: Jul | B17: =SUMIFS(Data!$R$2:$R$12000,Data!$W$2:$W$12000,$E17,Data!$V$2:$V$12000,Calc!$B$3,Data!$M$2:$M$12000,Calc!$B$4,Data!$O$2:$O$12000,Calc!$B$5,Data!$H$2:$H$12000,Calc!$B$6) -> 96817.35 | C17: =SUMIFS(Data!$U$2:$U$12000,Data!$W$2:$W$12000,$E17,Data!$V$2:$V$12000,Calc!$B$3,Data!$M$2:$M$12000,Calc!$B$4,Data!$O$2:$O$12000,Calc!$B$5,Data!$H$2:$H$12000,Calc!$B$6) -> 6119.41 | D17: =IF(B17=0,"",C17/B17) -> 0.063205717 | E17: 7
A18: Aug | B18: =SUMIFS(Data!$R$2:$R$12000,Data!$W$2:$W$12000,$E18,Data!$V$2:$V$12000,Calc!$B$3,Data!$M$2:$M$12000,Calc!$B$4,Data!$O$2:$O$12000,Calc!$B$5,Data!$H$2:$H$12000,Calc!$B$6) -> 58955.51 | C18: =SUMIFS(Data!$U$2:$U$12000,Data!$W$2:$W$12000,$E18,Data!$V$2:$V$12000,Calc!$B$3,Data!$M$2:$M$12000,Calc!$B$4,Data!$O$2:$O$12000,Calc!$B$5,Data!$H$2:$H$12000,Calc!$B$6) -> 3208.02 | D18: =IF(B18=0,"",C18/B18) -> 0.054414252 | E18: 8
A19: Sep | B19: =SUMIFS(Data!$R$2:$R$12000,Data!$W$2:$W$12000,$E19,Data!$V$2:$V$12000,Calc!$B$3,Data!$M$2:$M$12000,Calc!$B$4,Data!$O$2:$O$12000,Calc!$B$5,Data!$H$2:$H$12000,Calc!$B$6) -> 57290.21 | C19: =SUMIFS(Data!$U$2:$U$12000,Data!$W$2:$W$12000,$E19,Data!$V$2:$V$12000,Calc!$B$3,Data!$M$2:$M$12000,Calc!$B$4,Data!$O$2:$O$12000,Calc!$B$5,Data!$H$2:$H$12000,Calc!$B$6) -> 8047.15 | D19: =IF(B19=0,"",C19/B19) -> 0.14046292 | E19: 9
A20: Oct | B20: =SUMIFS(Data!$R$2:$R$12000,Data!$W$2:$W$12000,$E20,Data!$V$2:$V$12000,Calc!$B$3,Data!$M$2:$M$12000,Calc!$B$4,Data!$O$2:$O$12000,Calc!$B$5,Data!$H$2:$H$12000,Calc!$B$6) -> 42316.57 | C20: =SUMIFS(Data!$U$2:$U$12000,Data!$W$2:$W$12000,$E20,Data!$V$2:$V$12000,Calc!$B$3,Data!$M$2:$M$12000,Calc!$B$4,Data!$O$2:$O$12000,Calc!$B$5,Data!$H$2:$H$12000,Calc!$B$6) -> 3254.64 | D20: =IF(B20=0,"",C20/B20) -> 0.076911716 | E20: 10
A21: Nov | B21: =SUMIFS(Data!$R$2:$R$12000,Data!$W$2:$W$12000,$E21,Data!$V$2:$V$12000,Calc!$B$3,Data!$M$2:$M$12000,Calc!$B$4,Data!$O$2:$O$12000,Calc!$B$5,Data!$H$2:$H$12000,Calc!$B$6) -> 112563.77 | C21: =SUMIFS(Data!$U$2:$U$12000,Data!$W$2:$W$12000,$E21,Data!$V$2:$V$12000,Calc!$B$3,Data!$M$2:$M$12000,Calc!$B$4,Data!$O$2:$O$12000,Calc!$B$5,Data!$H$2:$H$12000,Calc!$B$6) -> 7585.41 | D21: =IF(B21=0,"",C21/B21) -> 0.067387668 | E21: 11
A22: Dec | B22: =SUMIFS(Data!$R$2:$R$12000,Data!$W$2:$W$12000,$E22,Data!$V$2:$V$12000,Calc!$B$3,Data!$M$2:$M$12000,Calc!$B$4,Data!$O$2:$O$12000,Calc!$B$5,Data!$H$2:$H$12000,Calc!$B$6) -> 96564.46 | C22: =SUMIFS(Data!$U$2:$U$12000,Data!$W$2:$W$12000,$E22,Data!$V$2:$V$12000,Calc!$B$3,Data!$M$2:$M$12000,Calc!$B$4,Data!$O$2:$O$12000,Calc!$B$5,Data!$H$2:$H$12000,Calc!$B$6) -> 2190.76 | D22: =IF(B22=0,"",C22/B22) -> 0.022687022 | E22: 12
A24: By year (ignores the Year filter)
A25: Year | B25: Sales | C25: Profit | D25: Margin
A26: 2014 | B26: =SUMIFS(Data!$R$2:$R$12000,Data!$V$2:$V$12000,$A26,Data!$M$2:$M$12000,Calc!$B$4,Data!$O$2:$O$12000,Calc!$B$5,Data!$H$2:$H$12000,Calc!$B$6) -> 194117.95 | C26: =SUMIFS(Data!$U$2:$U$12000,Data!$V$2:$V$12000,$A26,Data!$M$2:$M$12000,Calc!$B$4,Data!$O$2:$O$12000,Calc!$B$5,Data!$H$2:$H$12000,Calc!$B$6) -> 18956.81 | D26: =IF(B26=0,"",C26/B26) -> 0.097656142
A27: 2015 | B27: =SUMIFS(Data!$R$2:$R$12000,Data!$V$2:$V$12000,$A27,Data!$M$2:$M$12000,Calc!$B$4,Data!$O$2:$O$12000,Calc!$B$5,Data!$H$2:$H$12000,Calc!$B$6) -> 129288.59 | C27: =SUMIFS(Data!$U$2:$U$12000,Data!$V$2:$V$12000,$A27,Data!$M$2:$M$12000,Calc!$B$4,Data!$O$2:$O$12000,Calc!$B$5,Data!$H$2:$H$12000,Calc!$B$6) -> 6079.76 | D27: =IF(B27=0,"",C27/B27) -> 0.047024722
A28: 2016 | B28: =SUMIFS(Data!$R$2:$R$12000,Data!$V$2:$V$12000,$A28,Data!$M$2:$M$12000,Calc!$B$4,Data!$O$2:$O$12000,Calc!$B$5,Data!$H$2:$H$12000,Calc!$B$6) -> 218844.37 | C28: =SUMIFS(Data!$U$2:$U$12000,Data!$V$2:$V$12000,$A28,Data!$M$2:$M$12000,Calc!$B$4,Data!$O$2:$O$12000,Calc!$B$5,Data!$H$2:$H$12000,Calc!$B$6) -> 10682.47 | D28: =IF(B28=0,"",C28/B28) -> 0.04881309
A29: 2017 | B29: =SUMIFS(Data!$R$2:$R$12000,Data!$V$2:$V$12000,$A29,Data!$M$2:$M$12000,Calc!$B$4,Data!$O$2:$O$12000,Calc!$B$5,Data!$H$2:$H$12000,Calc!$B$6) -> 292566.71 | C29: =SUMIFS(Data!$U$2:$U$12000,Data!$V$2:$V$12000,$A29,Data!$M$2:$M$12000,Calc!$B$4,Data!$O$2:$O$12000,Calc!$B$5,Data!$H$2:$H$12000,Calc!$B$6) -> 21491.9 | D29: =IF(B29=0,"",C29/B29) -> 0.073459827
A31: By region (ignores the Region filter)
A32: Region | B32: Sales | C32: Profit | D32: Margin
A33: Central | B33: =SUMIFS(Data!$R$2:$R$12000,Data!$M$2:$M$12000,$A33,Data!$V$2:$V$12000,Calc!$B$3,Data!$O$2:$O$12000,Calc!$B$5,Data!$H$2:$H$12000,Calc!$B$6) -> 238441.91 | C33: =SUMIFS(Data!$U$2:$U$12000,Data!$M$2:$M$12000,$A33,Data!$V$2:$V$12000,Calc!$B$3,Data!$O$2:$O$12000,Calc!$B$5,Data!$H$2:$H$12000,Calc!$B$6) -> 12957.22 | D33: =IF(B33=0,"",C33/B33) -> 0.054341202
A34: East | B34: =SUMIFS(Data!$R$2:$R$12000,Data!$M$2:$M$12000,$A34,Data!$V$2:$V$12000,Calc!$B$3,Data!$O$2:$O$12000,Calc!$B$5,Data!$H$2:$H$12000,Calc!$B$6) -> 208079.93 | C34: =SUMIFS(Data!$U$2:$U$12000,Data!$M$2:$M$12000,$A34,Data!$V$2:$V$12000,Calc!$B$3,Data!$O$2:$O$12000,Calc!$B$5,Data!$H$2:$H$12000,Calc!$B$6) -> 24613.79 | D34: =IF(B34=0,"",C34/B34) -> 0.11829007
A35: South | B35: =SUMIFS(Data!$R$2:$R$12000,Data!$M$2:$M$12000,$A35,Data!$V$2:$V$12000,Calc!$B$3,Data!$O$2:$O$12000,Calc!$B$5,Data!$H$2:$H$12000,Calc!$B$6) -> 235783.76 | C35: =SUMIFS(Data!$U$2:$U$12000,Data!$M$2:$M$12000,$A35,Data!$V$2:$V$12000,Calc!$B$3,Data!$O$2:$O$12000,Calc!$B$5,Data!$H$2:$H$12000,Calc!$B$6) -> 19988.26 | D35: =IF(B35=0,"",C35/B35) -> 0.084773693
A36: West | B36: =SUMIFS(Data!$R$2:$R$12000,Data!$M$2:$M$12000,$A36,Data!$V$2:$V$12000,Calc!$B$3,Data!$O$2:$O$12000,Calc!$B$5,Data!$H$2:$H$12000,Calc!$B$6) -> 152512.02 | C36: =SUMIFS(Data!$U$2:$U$12000,Data!$M$2:$M$12000,$A36,Data!$V$2:$V$12000,Calc!$B$3,Data!$O$2:$O$12000,Calc!$B$5,Data!$H$2:$H$12000,Calc!$B$6) -> -348.33 | D36: =IF(B36=0,"",C36/B36) -> -0.0022839511
A38: By category (ignores the Category filter)
A39: Category | B39: Sales | C39: Profit | D39: Margin
A40: Furniture | B40: =SUMIFS(Data!$R$2:$R$12000,Data!$O$2:$O$12000,$A40,Data!$V$2:$V$12000,Calc!$B$3,Data!$M$2:$M$12000,Calc!$B$4,Data!$H$2:$H$12000,Calc!$B$6) -> 285063.27 | C40: =SUMIFS(Data!$U$2:$U$12000,Data!$O$2:$O$12000,$A40,Data!$V$2:$V$12000,Calc!$B$3,Data!$M$2:$M$12000,Calc!$B$4,Data!$H$2:$H$12000,Calc!$B$6) -> -18171.32 | D40: =IF(B40=0,"",C40/B40) -> -0.063744866
A41: Office Supplies | B41: =SUMIFS(Data!$R$2:$R$12000,Data!$O$2:$O$12000,$A41,Data!$V$2:$V$12000,Calc!$B$3,Data!$M$2:$M$12000,Calc!$B$4,Data!$H$2:$H$12000,Calc!$B$6) -> 125637.52 | C41: =SUMIFS(Data!$U$2:$U$12000,Data!$O$2:$O$12000,$A41,Data!$V$2:$V$12000,Calc!$B$3,Data!$M$2:$M$12000,Calc!$B$4,Data!$H$2:$H$12000,Calc!$B$6) -> 8769.54 | D41: =IF(B41=0,"",C41/B41) -> 0.069800327
A42: Technology | B42: =SUMIFS(Data!$R$2:$R$12000,Data!$O$2:$O$12000,$A42,Data!$V$2:$V$12000,Calc!$B$3,Data!$M$2:$M$12000,Calc!$B$4,Data!$H$2:$H$12000,Calc!$B$6) -> 424116.83 | C42: =SUMIFS(Data!$U$2:$U$12000,Data!$O$2:$O$12000,$A42,Data!$V$2:$V$12000,Calc!$B$3,Data!$M$2:$M$12000,Calc!$B$4,Data!$H$2:$H$12000,Calc!$B$6) -> 66612.72 | D42: =IF(B42=0,"",C42/B42) -> 0.15706219
A44: By segment (ignores the Segment filter)
A45: Segment | B45: Sales | C45: Profit | D45: Margin
A46: Consumer | B46: =SUMIFS(Data!$R$2:$R$12000,Data!$H$2:$H$12000,$A46,Data!$V$2:$V$12000,Calc!$B$3,Data!$M$2:$M$12000,Calc!$B$4,Data!$O$2:$O$12000,Calc!$B$5) -> 442265.17 | C46: =SUMIFS(Data!$U$2:$U$12000,Data!$H$2:$H$12000,$A46,Data!$V$2:$V$12000,Calc!$B$3,Data!$M$2:$M$12000,Calc!$B$4,Data!$O$2:$O$12000,Calc!$B$5) -> 34558.83 | D46: =IF(B46=0,"",C46/B46) -> 0.078140519
A47: Corporate | B47: =SUMIFS(Data!$R$2:$R$12000,Data!$H$2:$H$12000,$A47,Data!$V$2:$V$12000,Calc!$B$3,Data!$M$2:$M$12000,Calc!$B$4,Data!$O$2:$O$12000,Calc!$B$5) -> 296170.85 | C47: =SUMIFS(Data!$U$2:$U$12000,Data!$H$2:$H$12000,$A47,Data!$V$2:$V$12000,Calc!$B$3,Data!$M$2:$M$12000,Calc!$B$4,Data!$O$2:$O$12000,Calc!$B$5) -> 20036.9 | D47: =IF(B47=0,"",C47/B47) -> 0.067653181
...
